Ultralytics 8.3.154  Python-3.11.13 torch-2.7.1+cpu CPU (Intel Core(TM) i5-1035G1 1.00GHz)
[34m[1mengine\trainer: [0magnostic_nms=False, amp=True, augment=False, auto_augment=randaugment, batch=16, bgr=0.0, box=7.5, cache=False, cfg=None, classes=None, close_mosaic=10, cls=0.5, conf=None, copy_paste=0.0, copy_paste_mode=flip, cos_lr=False, cutmix=0.0, data=D:\Internship_Tasks\Maharshi_Animal-_and_Human_Detection_Model\YOLO_detection_model\datasets\openimages_yolo\data.yaml, degrees=0.0, deterministic=True, device=cpu, dfl=1.5, dnn=False, dropout=0.0, dynamic=False, embed=None, epochs=30, erasing=0.4, exist_ok=False, fliplr=0.5, flipud=0.0, format=torchscript, fraction=1.0, freeze=None, half=False, hsv_h=0.015, hsv_s=0.7, hsv_v=0.4, imgsz=640, int8=False, iou=0.7, keras=False, kobj=1.0, line_width=None, lr0=0.01, lrf=0.01, mask_ratio=4, max_det=300, mixup=0.0, mode=train, model=yolov8n.pt, momentum=0.937, mosaic=1.0, multi_scale=False, name=oi_yolov8_direct4, nbs=64, nms=False, opset=None, optimize=False, optimizer=auto, overlap_mask=True, patience=100, perspective=0.0, plots=True, pose=12.0, pretrained=True, profile=False, project=runs/train, rect=False, resume=False, retina_masks=False, save=True, save_conf=False, save_crop=False, save_dir=runs\train\oi_yolov8_direct4, save_frames=False, save_json=False, save_period=-1, save_txt=False, scale=0.5, seed=0, shear=0.0, show=False, show_boxes=True, show_conf=True, show_labels=True, simplify=True, single_cls=False, source=None, split=val, stream_buffer=False, task=detect, time=None, tracker=botsort.yaml, translate=0.1, val=True, verbose=True, vid_stride=1, visualize=False, warmup_bias_lr=0.1, warmup_epochs=3.0, warmup_momentum=0.8, weight_decay=0.0005, workers=8, workspace=None
Traceback (most recent call last):
  File "C:\Users\dhaba\anaconda3\envs\MH\Lib\site-packages\ultralytics\engine\trainer.py", line 607, in get_dataset
    data = check_det_dataset(self.args.data)
           ^^^^^^^^^^^^^^^^^^^^^^^^^^^^^^^^^
  File "C:\Users\dhaba\anaconda3\envs\MH\Lib\site-packages\ultralytics\data\utils.py", line 463, in check_det_dataset
    raise FileNotFoundError(m)
FileNotFoundError: Dataset 'D://Internship_Tasks/Maharshi_Animal-_and_Human_Detection_Model/YOLO_detection_model/datasets/openimages_yolo/data.yaml' images not found, missing path 'D:\Internship_Tasks\Maharshi_Animal-_and_Human_Detection_Model\animal_person_classifier\datasets\datasets\openimages_yolo\images\val'
Note dataset download directory is 'D:\Internship_Tasks\Maharshi_Animal-_and_Human_Detection_Model\animal_person_classifier\datasets'. You can update this in 'C:\Users\dhaba\AppData\Roaming\Ultralytics\settings.json'

The above exception was the direct cause of the following exception:

Traceback (most recent call last):
  File "d:\Internship_Tasks\Maharshi_Animal-_and_Human_Detection_Model\YOLO_detection_model\main.py", line 23, in <module>
    model.train(
  File "C:\Users\dhaba\anaconda3\envs\MH\Lib\site-packages\ultralytics\engine\model.py", line 791, in train
    self.trainer = (trainer or self._smart_load("trainer"))(overrides=args, _callbacks=self.callbacks)
                   ^^^^^^^^^^^^^^^^^^^^^^^^^^^^^^^^^^^^^^^^^^^^^^^^^^^^^^^^^^^^^^^^^^^^^^^^^^^^^^^^^^^
  File "C:\Users\dhaba\anaconda3\envs\MH\Lib\site-packages\ultralytics\engine\trainer.py", line 153, in __init__
    self.data = self.get_dataset()
                ^^^^^^^^^^^^^^^^^^
  File "C:\Users\dhaba\anaconda3\envs\MH\Lib\site-packages\ultralytics\engine\trainer.py", line 611, in get_dataset
    raise RuntimeError(emojis(f"Dataset '{clean_url(self.args.data)}' error ‚ùå {e}")) from e
RuntimeError: Dataset 'D://Internship_Tasks/Maharshi_Animal-_and_Human_Detection_Model/YOLO_detection_model/datasets/openimages_yolo/data.yaml' error  Dataset 'D://Internship_Tasks/Maharshi_Animal-_and_Human_Detection_Model/YOLO_detection_model/datasets/openimages_yolo/data.yaml' images not found, missing path 'D:\Internship_Tasks\Maharshi_Animal-_and_Human_Detection_Model\animal_person_classifier\datasets\datasets\openimages_yolo\images\val'
Note dataset download directory is 'D:\Internship_Tasks\Maharshi_Animal-_and_Human_Detection_Model\animal_person_classifier\datasets'. You can update this in 'C:\Users\dhaba\AppData\Roaming\Ultralytics\settings.json'
Traceback (most recent call last):
  File "C:\Users\dhaba\anaconda3\envs\MH\Lib\site-packages\ultralytics\engine\trainer.py", line 607, in get_dataset
    data = check_det_dataset(self.args.data)
           ^^^^^^^^^^^^^^^^^^^^^^^^^^^^^^^^^
  File "C:\Users\dhaba\anaconda3\envs\MH\Lib\site-packages\ultralytics\data\utils.py", line 463, in check_det_dataset
    raise FileNotFoundError(m)
FileNotFoundError: Dataset 'D://Internship_Tasks/Maharshi_Animal-_and_Human_Detection_Model/YOLO_detection_model/datasets/openimages_yolo/data.yaml' images not found, missing path 'D:\Internship_Tasks\Maharshi_Animal-_and_Human_Detection_Model\animal_person_classifier\datasets\datasets\openimages_yolo\images\val'
Note dataset download directory is 'D:\Internship_Tasks\Maharshi_Animal-_and_Human_Detection_Model\animal_person_classifier\datasets'. You can update this in 'C:\Users\dhaba\AppData\Roaming\Ultralytics\settings.json'

The above exception was the direct cause of the following exception:

Traceback (most recent call last):
  File "d:\Internship_Tasks\Maharshi_Animal-_and_Human_Detection_Model\YOLO_detection_model\main.py", line 23, in <module>
    model.train(
  File "C:\Users\dhaba\anaconda3\envs\MH\Lib\site-packages\ultralytics\engine\model.py", line 791, in train
    self.trainer = (trainer or self._smart_load("trainer"))(overrides=args, _callbacks=self.callbacks)
                   ^^^^^^^^^^^^^^^^^^^^^^^^^^^^^^^^^^^^^^^^^^^^^^^^^^^^^^^^^^^^^^^^^^^^^^^^^^^^^^^^^^^
  File "C:\Users\dhaba\anaconda3\envs\MH\Lib\site-packages\ultralytics\engine\trainer.py", line 153, in __init__
    self.data = self.get_dataset()
                ^^^^^^^^^^^^^^^^^^
  File "C:\Users\dhaba\anaconda3\envs\MH\Lib\site-packages\ultralytics\engine\trainer.py", line 611, in get_dataset
    raise RuntimeError(emojis(f"Dataset '{clean_url(self.args.data)}' error ‚ùå {e}")) from e
RuntimeError: Dataset 'D://Internship_Tasks/Maharshi_Animal-_and_Human_Detection_Model/YOLO_detection_model/datasets/openimages_yolo/data.yaml' error  Dataset 'D://Internship_Tasks/Maharshi_Animal-_and_Human_Detection_Model/YOLO_detection_model/datasets/openimages_yolo/data.yaml' images not found, missing path 'D:\Internship_Tasks\Maharshi_Animal-_and_Human_Detection_Model\animal_person_classifier\datasets\datasets\openimages_yolo\images\val'
Note dataset download directory is 'D:\Internship_Tasks\Maharshi_Animal-_and_Human_Detection_Model\animal_person_classifier\datasets'. You can update this in 'C:\Users\dhaba\AppData\Roaming\Ultralytics\settings.json'
